{
 "cells": [
  {
   "cell_type": "code",
   "execution_count": 1,
   "id": "b0239cab",
   "metadata": {},
   "outputs": [],
   "source": [
    "import requests"
   ]
  },
  {
   "cell_type": "code",
   "execution_count": 2,
   "id": "b9c117c5",
   "metadata": {},
   "outputs": [],
   "source": [
    "import pandas as pd"
   ]
  },
  {
   "cell_type": "code",
   "execution_count": 6,
   "id": "6b52180a",
   "metadata": {},
   "outputs": [
    {
     "name": "stdout",
     "output_type": "stream",
     "text": [
      "Requirement already satisfied: BeautifulSoup4 in c:\\users\\502770913\\anaconda3\\lib\\site-packages (4.10.0)\n",
      "Requirement already satisfied: soupsieve>1.2 in c:\\users\\502770913\\anaconda3\\lib\\site-packages (from BeautifulSoup4) (2.2.1)\n"
     ]
    },
    {
     "ename": "ModuleNotFoundError",
     "evalue": "No module named 'BeautifulSoup4'",
     "output_type": "error",
     "traceback": [
      "\u001b[1;31m---------------------------------------------------------------------------\u001b[0m",
      "\u001b[1;31mModuleNotFoundError\u001b[0m                       Traceback (most recent call last)",
      "\u001b[1;32mC:\\Users\\502770~1\\AppData\\Local\\Temp\\1/ipykernel_18952/402705881.py\u001b[0m in \u001b[0;36m<module>\u001b[1;34m\u001b[0m\n\u001b[0;32m      1\u001b[0m \u001b[0mget_ipython\u001b[0m\u001b[1;33m(\u001b[0m\u001b[1;33m)\u001b[0m\u001b[1;33m.\u001b[0m\u001b[0msystem\u001b[0m\u001b[1;33m(\u001b[0m\u001b[1;34m'pip install BeautifulSoup4'\u001b[0m\u001b[1;33m)\u001b[0m\u001b[1;33m\u001b[0m\u001b[1;33m\u001b[0m\u001b[0m\n\u001b[1;32m----> 2\u001b[1;33m \u001b[1;32mimport\u001b[0m \u001b[0mBeautifulSoup4\u001b[0m \u001b[1;32mas\u001b[0m \u001b[0mbs4\u001b[0m\u001b[1;33m\u001b[0m\u001b[1;33m\u001b[0m\u001b[0m\n\u001b[0m",
      "\u001b[1;31mModuleNotFoundError\u001b[0m: No module named 'BeautifulSoup4'"
     ]
    }
   ],
   "source": [
    "!pip install BeautifulSoup4 \n",
    "import BeautifulSoup4 as bs4"
   ]
  },
  {
   "cell_type": "code",
   "execution_count": 7,
   "id": "5bc7c2ce",
   "metadata": {},
   "outputs": [
    {
     "ename": "ModuleNotFoundError",
     "evalue": "No module named 'BeautifulSoup'",
     "output_type": "error",
     "traceback": [
      "\u001b[1;31m---------------------------------------------------------------------------\u001b[0m",
      "\u001b[1;31mModuleNotFoundError\u001b[0m                       Traceback (most recent call last)",
      "\u001b[1;32mC:\\Users\\502770~1\\AppData\\Local\\Temp\\1/ipykernel_18952/1070298794.py\u001b[0m in \u001b[0;36m<module>\u001b[1;34m\u001b[0m\n\u001b[1;32m----> 1\u001b[1;33m \u001b[1;32mimport\u001b[0m \u001b[0mBeautifulSoup\u001b[0m \u001b[1;32mas\u001b[0m \u001b[0mbs\u001b[0m\u001b[1;33m\u001b[0m\u001b[1;33m\u001b[0m\u001b[0m\n\u001b[0m",
      "\u001b[1;31mModuleNotFoundError\u001b[0m: No module named 'BeautifulSoup'"
     ]
    }
   ],
   "source": [
    "import BeautifulSoup as bs"
   ]
  },
  {
   "cell_type": "code",
   "execution_count": 8,
   "id": "44f9e99d",
   "metadata": {},
   "outputs": [
    {
     "name": "stdout",
     "output_type": "stream",
     "text": [
      "Could not fetch URL https://pypi.org/simple/beautifulsoup3/: There was a problem confirming the ssl certificate: HTTPSConnectionPool(host='pypi.org', port=443): Max retries exceeded with url: /simple/beautifulsoup3/ (Caused by SSLError(SSLCertVerificationError(1, '[SSL: CERTIFICATE_VERIFY_FAILED] certificate verify failed: self signed certificate in certificate chain (_ssl.c:1129)'))) - skipping"
     ]
    },
    {
     "name": "stderr",
     "output_type": "stream",
     "text": [
      "WARNING: Retrying (Retry(total=4, connect=None, read=None, redirect=None, status=None)) after connection broken by 'SSLError(SSLCertVerificationError(1, '[SSL: CERTIFICATE_VERIFY_FAILED] certificate verify failed: self signed certificate in certificate chain (_ssl.c:1129)'))': /simple/beautifulsoup3/\n",
      "WARNING: Retrying (Retry(total=3, connect=None, read=None, redirect=None, status=None)) after connection broken by 'SSLError(SSLCertVerificationError(1, '[SSL: CERTIFICATE_VERIFY_FAILED] certificate verify failed: self signed certificate in certificate chain (_ssl.c:1129)'))': /simple/beautifulsoup3/\n",
      "WARNING: Retrying (Retry(total=2, connect=None, read=None, redirect=None, status=None)) after connection broken by 'SSLError(SSLCertVerificationError(1, '[SSL: CERTIFICATE_VERIFY_FAILED] certificate verify failed: self signed certificate in certificate chain (_ssl.c:1129)'))': /simple/beautifulsoup3/\n",
      "WARNING: Retrying (Retry(total=1, connect=None, read=None, redirect=None, status=None)) after connection broken by 'SSLError(SSLCertVerificationError(1, '[SSL: CERTIFICATE_VERIFY_FAILED] certificate verify failed: self signed certificate in certificate chain (_ssl.c:1129)'))': /simple/beautifulsoup3/\n",
      "WARNING: Retrying (Retry(total=0, connect=None, read=None, redirect=None, status=None)) after connection broken by 'SSLError(SSLCertVerificationError(1, '[SSL: CERTIFICATE_VERIFY_FAILED] certificate verify failed: self signed certificate in certificate chain (_ssl.c:1129)'))': /simple/beautifulsoup3/\n",
      "ERROR: Could not find a version that satisfies the requirement BeautifulSoup3 (from versions: none)\n",
      "ERROR: No matching distribution found for BeautifulSoup3\n"
     ]
    },
    {
     "name": "stdout",
     "output_type": "stream",
     "text": [
      "\n"
     ]
    }
   ],
   "source": [
    "!pip install BeautifulSoup3"
   ]
  },
  {
   "cell_type": "code",
   "execution_count": null,
   "id": "f6614ca4",
   "metadata": {},
   "outputs": [],
   "source": []
  }
 ],
 "metadata": {
  "kernelspec": {
   "display_name": "Python 3 (ipykernel)",
   "language": "python",
   "name": "python3"
  },
  "language_info": {
   "codemirror_mode": {
    "name": "ipython",
    "version": 3
   },
   "file_extension": ".py",
   "mimetype": "text/x-python",
   "name": "python",
   "nbconvert_exporter": "python",
   "pygments_lexer": "ipython3",
   "version": "3.9.7"
  }
 },
 "nbformat": 4,
 "nbformat_minor": 5
}
